2025-06-09 14:13:30,350 - INFO - 1. TEFAS fiyat indiriliyor ba\u015fl\u0131yor...
2025-06-09 14:13:33,274 - ERROR - 1. TEFAS fiyat indiriliyor s\u0131ras\u0131nda hata: Traceback (most recent call last):
  File "C:\Users\yahya\Documents\fund_price_upload\tefas_fiyat_indir_pp_uyumlu.py", line 23, in <module>
    print(f"\n---\n{fon_adi} için i\u015flem ba\u015flat\u0131l\u0131yor...")
  File "C:\Users\yahya\anaconda3\Lib\encodings\cp1252.py", line 19, in encode
    return codecs.charmap_encode(input,self.errors,encoding_table)[0]
           ^^^^^^^^^^^^^^^^^^^^^^^^^^^^^^^^^^^^^^^^^^^^^^^^^^^^^^^
UnicodeEncodeError: 'charmap' codec can't encode character '\u015f' in position 17: character maps to <undefined>

2025-06-09 14:20:19,549 - INFO - 1. TEFAS fiyat indiriliyor ba\u015fl\u0131yor...
2025-06-09 14:20:22,511 - ERROR - 1. TEFAS fiyat indiriliyor s\u0131ras\u0131nda hata: Traceback (most recent call last):
  File "C:\Users\yahya\Documents\fund_price_upload\tefas_fiyat_indir_pp_uyumlu.py", line 23, in <module>
    print(f"\n---\n{fon_adi} için i\u015flem ba\u015flat\u0131l\u0131yor...")
  File "C:\Users\yahya\anaconda3\Lib\encodings\cp1252.py", line 19, in encode
    return codecs.charmap_encode(input,self.errors,encoding_table)[0]
           ^^^^^^^^^^^^^^^^^^^^^^^^^^^^^^^^^^^^^^^^^^^^^^^^^^^^^^^
UnicodeEncodeError: 'charmap' codec can't encode character '\u015f' in position 17: character maps to <undefined>

2025-06-09 14:22:10,918 - INFO - 1. TEFAS fiyat indiriliyor basliyor...
2025-06-09 14:22:13,719 - ERROR - 1. TEFAS fiyat indiriliyor sirasinda hata: Traceback (most recent call last):
  File "C:\Users\yahya\Documents\fund_price_upload\tefas_fiyat_indir_pp_uyumlu.py", line 23, in <module>
    print(f"\n---\n{fon_adi} için i\u015flem ba\u015flat\u0131l\u0131yor...")
  File "C:\Users\yahya\anaconda3\Lib\encodings\cp1252.py", line 19, in encode
    return codecs.charmap_encode(input,self.errors,encoding_table)[0]
           ^^^^^^^^^^^^^^^^^^^^^^^^^^^^^^^^^^^^^^^^^^^^^^^^^^^^^^^
UnicodeEncodeError: 'charmap' codec can't encode character '\u015f' in position 17: character maps to <undefined>

2025-06-09 14:23:41,910 - INFO - 1. TEFAS fiyat indiriliyor basliyor...
2025-06-09 14:23:45,090 - ERROR - 1. TEFAS fiyat indiriliyor sirasinda hata: Traceback (most recent call last):
  File "C:\Users\yahya\Documents\fund_price_upload\tefas_fiyat_indir_pp_uyumlu.py", line 83, in <module>
    combined_data_pp["Date"] = pd.to_datetime(combined_data_pp["Date"]).dt.strftime("%Y-%m-%d")
                               ^^^^^^^^^^^^^^^^^^^^^^^^^^^^^^^^^^^^^^^^
  File "C:\Users\yahya\anaconda3\Lib\site-packages\pandas\core\tools\datetimes.py", line 1070, in to_datetime
    result = _assemble_from_unit_mappings(arg, errors, utc)
             ^^^^^^^^^^^^^^^^^^^^^^^^^^^^^^^^^^^^^^^^^^^^^^
  File "C:\Users\yahya\anaconda3\Lib\site-packages\pandas\core\tools\datetimes.py", line 1165, in _assemble_from_unit_mappings
    raise ValueError("cannot assemble with duplicate keys")
ValueError: cannot assemble with duplicate keys

2025-06-09 14:28:04,423 - INFO - 1. TEFAS fiyat indiriliyor basliyor...
2025-06-09 14:28:07,579 - ERROR - 1. TEFAS fiyat indiriliyor sirasinda hata: Traceback (most recent call last):
  File "C:\Users\yahya\Documents\fund_price_upload\tefas_fiyat_indir_pp_uyumlu.py", line 74, in <module>
    combined_data_pp["Date"] = pd.to_datetime(combined_data_pp["Date"]).dt.strftime("%Y-%m-%d")
                               ^^^^^^^^^^^^^^^^^^^^^^^^^^^^^^^^^^^^^^^^
  File "C:\Users\yahya\anaconda3\Lib\site-packages\pandas\core\tools\datetimes.py", line 1070, in to_datetime
    result = _assemble_from_unit_mappings(arg, errors, utc)
             ^^^^^^^^^^^^^^^^^^^^^^^^^^^^^^^^^^^^^^^^^^^^^^
  File "C:\Users\yahya\anaconda3\Lib\site-packages\pandas\core\tools\datetimes.py", line 1165, in _assemble_from_unit_mappings
    raise ValueError("cannot assemble with duplicate keys")
ValueError: cannot assemble with duplicate keys

2025-06-09 14:29:51,242 - INFO - 1. TEFAS fiyat indiriliyor basliyor...
2025-06-09 14:29:54,342 - ERROR - 1. TEFAS fiyat indiriliyor sirasinda hata: Traceback (most recent call last):
  File "C:\Users\yahya\Documents\fund_price_upload\tefas_fiyat_indir_pp_uyumlu.py", line 76, in <module>
    combined_data_pp.columns = ["Date", "Close"]
    ^^^^^^^^^^^^^^^^^^^^^^^^
  File "C:\Users\yahya\anaconda3\Lib\site-packages\pandas\core\generic.py", line 6313, in __setattr__
    return object.__setattr__(self, name, value)
           ^^^^^^^^^^^^^^^^^^^^^^^^^^^^^^^^^^^^^
  File "properties.pyx", line 69, in pandas._libs.properties.AxisProperty.__set__
  File "C:\Users\yahya\anaconda3\Lib\site-packages\pandas\core\generic.py", line 814, in _set_axis
    self._mgr.set_axis(axis, labels)
  File "C:\Users\yahya\anaconda3\Lib\site-packages\pandas\core\internals\managers.py", line 238, in set_axis
    self._validate_set_axis(axis, new_labels)
  File "C:\Users\yahya\anaconda3\Lib\site-packages\pandas\core\internals\base.py", line 98, in _validate_set_axis
    raise ValueError(
ValueError: Length mismatch: Expected axis has 3 elements, new values have 2 elements

2025-06-09 14:33:43,072 - INFO - 1. TEFAS fiyat indiriliyor basliyor...
2025-06-09 14:33:46,820 - INFO - 1. TEFAS fiyat indiriliyor tamamlandi.
2025-06-09 14:33:46,820 - INFO - 2. HTML dosyalari uretiliyor basliyor...
2025-06-09 14:33:46,929 - ERROR - 2. HTML dosyalari uretiliyor sirasinda hata: python: can't open file 'C:\\Users\\yahya\\Documents\\fund_price_upload\\convert_to_html.py': [Errno 2] No such file or directory

2025-06-09 14:34:30,010 - INFO - 1. TEFAS fiyat indiriliyor basliyor...
2025-06-09 14:34:33,739 - INFO - 1. TEFAS fiyat indiriliyor tamamlandi.
2025-06-09 14:34:33,739 - INFO - 2. HTML dosyalari uretiliyor basliyor...
2025-06-09 14:34:35,271 - INFO - 2. HTML dosyalari uretiliyor tamamlandi.
2025-06-09 14:34:35,271 - INFO - 3. GitHub'a yukleniyor basliyor...
2025-06-09 14:34:38,100 - INFO - 3. GitHub'a yukleniyor tamamlandi.
2025-06-09 14:34:38,116 - INFO - Silinecek HTML dosyasi bulunamadi.
2025-06-09 15:06:47,359 - INFO - 1. TEFAS fiyat indiriliyor basliyor...
2025-06-09 15:07:40,212 - INFO - 1. TEFAS fiyat indiriliyor tamamlandi.
2025-06-09 15:07:40,212 - INFO - 2. HTML dosyalari uretiliyor basliyor...
2025-06-09 15:07:41,884 - INFO - 2. HTML dosyalari uretiliyor tamamlandi.
2025-06-09 15:07:41,884 - INFO - 3. GitHub'a yukleniyor basliyor...
2025-06-09 15:07:44,785 - INFO - 3. GitHub'a yukleniyor tamamlandi.
2025-06-09 15:07:44,793 - INFO - Silinecek HTML dosyasi bulunamadi.
2025-06-09 15:14:45,986 - INFO - 1. TEFAS fiyat indiriliyor basliyor...
2025-06-09 15:15:38,852 - INFO - 1. TEFAS fiyat indiriliyor tamamlandi.
2025-06-09 15:15:38,852 - INFO - 2. HTML dosyalari uretiliyor basliyor...
2025-06-09 15:15:40,463 - INFO - 2. HTML dosyalari uretiliyor tamamlandi.
2025-06-09 15:15:40,463 - INFO - 3. GitHub'a yukleniyor basliyor...
2025-06-09 15:15:41,044 - ERROR - 3. GitHub'a yukleniyor sirasinda hata: Traceback (most recent call last):
  File "C:\Users\yahya\Documents\fund_price_upload\html_yayinlarini_yukle.py", line 20, in <module>
    repo.git.rm("-r", "--cached", "html_yayin")
  File "C:\Users\yahya\anaconda3\Lib\site-packages\git\cmd.py", line 739, in <lambda>
    return lambda *args, **kwargs: self._call_process(name, *args, **kwargs)
                                   ^^^^^^^^^^^^^^^^^^^^^^^^^^^^^^^^^^^^^^^^^
  File "C:\Users\yahya\anaconda3\Lib\site-packages\git\cmd.py", line 1315, in _call_process
    return self.execute(call, **exec_kwargs)
           ^^^^^^^^^^^^^^^^^^^^^^^^^^^^^^^^^
  File "C:\Users\yahya\anaconda3\Lib\site-packages\git\cmd.py", line 1110, in execute
    raise GitCommandError(redacted_command, status, stderr_value, stdout_value)
git.exc.GitCommandError: Cmd('git') failed due to: exit code(128)
  cmdline: git rm -r --cached html_yayin
  stderr: 'fatal: pathspec 'html_yayin' did not match any files'

2025-06-09 15:18:34,616 - INFO - 1. TEFAS fiyat indiriliyor basliyor...
2025-06-09 15:18:34,727 - ERROR - 1. TEFAS fiyat indiriliyor sirasinda hata: python: can't open file 'C:\\Users\\yahya\\Documents\\fund_price_upload\\tefas_fiyat_indir_pp_uyumlu_final.py': [Errno 2] No such file or directory

2025-06-09 15:19:00,687 - INFO - 1. TEFAS fiyat indiriliyor basliyor...
2025-06-09 15:19:53,623 - INFO - 1. TEFAS fiyat indiriliyor tamamlandi.
2025-06-09 15:19:53,623 - INFO - 2. HTML dosyalari uretiliyor basliyor...
2025-06-09 15:19:55,196 - INFO - 2. HTML dosyalari uretiliyor tamamlandi.
2025-06-09 15:19:55,196 - INFO - 3. GitHub'a yukleniyor basliyor...
2025-06-09 15:19:55,298 - ERROR - 3. GitHub'a yukleniyor sirasinda hata: python: can't open file 'C:\\Users\\yahya\\Documents\\fund_price_upload\\html_yayinlarini_yukle.py': [Errno 2] No such file or directory

2025-06-09 15:20:24,472 - INFO - 1. TEFAS fiyat indiriliyor basliyor...
2025-06-09 15:21:30,951 - ERROR - 1. TEFAS fiyat indiriliyor sirasinda hata: C:\Users\yahya\Documents\fund_price_upload\tefas_fiyat_indir_pp_uyumlu_final.py:65: FutureWarning: The behavior of DataFrame concatenation with empty or all-NA entries is deprecated. In a future version, this will no longer exclude empty or all-NA columns when determining the result dtypes. To retain the old behavior, exclude the relevant entries before the concat operation.
  new_data = pd.concat(new_data_frames, ignore_index=True)
Traceback (most recent call last):
  File "C:\Users\yahya\anaconda3\Lib\site-packages\urllib3\connectionpool.py", line 789, in urlopen
    response = self._make_request(
               ^^^^^^^^^^^^^^^^^^^
  File "C:\Users\yahya\anaconda3\Lib\site-packages\urllib3\connectionpool.py", line 536, in _make_request
    response = conn.getresponse()
               ^^^^^^^^^^^^^^^^^^
  File "C:\Users\yahya\anaconda3\Lib\site-packages\urllib3\connection.py", line 464, in getresponse
    httplib_response = super().getresponse()
                       ^^^^^^^^^^^^^^^^^^^^^
  File "C:\Users\yahya\anaconda3\Lib\http\client.py", line 1428, in getresponse
    response.begin()
  File "C:\Users\yahya\anaconda3\Lib\http\client.py", line 331, in begin
    version, status, reason = self._read_status()
                              ^^^^^^^^^^^^^^^^^^^
  File "C:\Users\yahya\anaconda3\Lib\http\client.py", line 300, in _read_status
    raise RemoteDisconnected("Remote end closed connection without"
http.client.RemoteDisconnected: Remote end closed connection without response

During handling of the above exception, another exception occurred:

Traceback (most recent call last):
  File "C:\Users\yahya\anaconda3\Lib\site-packages\requests\adapters.py", line 589, in send
    resp = conn.urlopen(
           ^^^^^^^^^^^^^
  File "C:\Users\yahya\anaconda3\Lib\site-packages\urllib3\connectionpool.py", line 843, in urlopen
    retries = retries.increment(
              ^^^^^^^^^^^^^^^^^^
  File "C:\Users\yahya\anaconda3\Lib\site-packages\urllib3\util\retry.py", line 474, in increment
    raise reraise(type(error), error, _stacktrace)
          ^^^^^^^^^^^^^^^^^^^^^^^^^^^^^^^^^^^^^^^^
  File "C:\Users\yahya\anaconda3\Lib\site-packages\urllib3\util\util.py", line 38, in reraise
    raise value.with_traceback(tb)
  File "C:\Users\yahya\anaconda3\Lib\site-packages\urllib3\connectionpool.py", line 789, in urlopen
    response = self._make_request(
               ^^^^^^^^^^^^^^^^^^^
  File "C:\Users\yahya\anaconda3\Lib\site-packages\urllib3\connectionpool.py", line 536, in _make_request
    response = conn.getresponse()
               ^^^^^^^^^^^^^^^^^^
  File "C:\Users\yahya\anaconda3\Lib\site-packages\urllib3\connection.py", line 464, in getresponse
    httplib_response = super().getresponse()
                       ^^^^^^^^^^^^^^^^^^^^^
  File "C:\Users\yahya\anaconda3\Lib\http\client.py", line 1428, in getresponse
    response.begin()
  File "C:\Users\yahya\anaconda3\Lib\http\client.py", line 331, in begin
    version, status, reason = self._read_status()
                              ^^^^^^^^^^^^^^^^^^^
  File "C:\Users\yahya\anaconda3\Lib\http\client.py", line 300, in _read_status
    raise RemoteDisconnected("Remote end closed connection without"
urllib3.exceptions.ProtocolError: ('Connection aborted.', RemoteDisconnected('Remote end closed connection without response'))

During handling of the above exception, another exception occurred:

Traceback (most recent call last):
  File "C:\Users\yahya\Documents\fund_price_upload\tefas_fiyat_indir_pp_uyumlu_final.py", line 59, in <module>
    df = tefas.fetch(start=str(month_start), end=str(interval_end), name=fon_adi, columns=["date", "price"])
         ^^^^^^^^^^^^^^^^^^^^^^^^^^^^^^^^^^^^^^^^^^^^^^^^^^^^^^^^^^^^^^^^^^^^^^^^^^^^^^^^^^^^^^^^^^^^^^^^^^^
  File "C:\Users\yahya\anaconda3\Lib\site-packages\tefas\crawler.py", line 105, in fetch
    info = self._do_post(self.info_endpoint, data)
           ^^^^^^^^^^^^^^^^^^^^^^^^^^^^^^^^^^^^^^^
  File "C:\Users\yahya\anaconda3\Lib\site-packages\tefas\crawler.py", line 126, in _do_post
    response = self.session.post(
               ^^^^^^^^^^^^^^^^^^
  File "C:\Users\yahya\anaconda3\Lib\site-packages\requests\sessions.py", line 637, in post
    return self.request("POST", url, data=data, json=json, **kwargs)
           ^^^^^^^^^^^^^^^^^^^^^^^^^^^^^^^^^^^^^^^^^^^^^^^^^^^^^^^^^
  File "C:\Users\yahya\anaconda3\Lib\site-packages\requests\sessions.py", line 589, in request
    resp = self.send(prep, **send_kwargs)
           ^^^^^^^^^^^^^^^^^^^^^^^^^^^^^^
  File "C:\Users\yahya\anaconda3\Lib\site-packages\requests\sessions.py", line 703, in send
    r = adapter.send(request, **kwargs)
        ^^^^^^^^^^^^^^^^^^^^^^^^^^^^^^^
  File "C:\Users\yahya\anaconda3\Lib\site-packages\requests\adapters.py", line 604, in send
    raise ConnectionError(err, request=request)
requests.exceptions.ConnectionError: ('Connection aborted.', RemoteDisconnected('Remote end closed connection without response'))

2025-06-09 15:21:40,656 - INFO - 1. TEFAS fiyat indiriliyor basliyor...
2025-06-09 15:22:00,109 - INFO - 1. TEFAS fiyat indiriliyor tamamlandi.
2025-06-09 15:22:00,109 - INFO - 2. HTML dosyalari uretiliyor basliyor...
